Workbook

Sheet Instructions
B2: Multi-Client Month-End Close Tracker
B3: For accounting firms running month-end close across many clients at once.
B5: How it works
B6: 1. On the Clients sheet, list every client you close each month in the yellow input cells: entity count, accounting software, the close owner at your firm, and the target number of days to close.
B7: 2. On the Close Tracker sheet, add one row per client per task. Pick the Client, Task, and Status from the dropdowns, then enter the Due Date and, once finished, the Completed Date.
B8: 3. Days Late computes automatically: if a task was completed after its due date, it shows how many days late; otherwise 0. It stays blank until both dates are filled.
B9: 4. The Summary sheet rolls everything up per client with formulas only: total tasks, tasks done, percent complete, blocked count, days to close so far, and how that compares with the client's target. A firm-level totals row sits at the bottom.
B11: Monthly workflow
B12: At the start of each month, right-click the Close Tracker tab and choose Move or Copy > Create a copy. Rename the copy for the new period (for example, Close Tracker Jul), clear the Completed Date and reset Status to Not started, and update the Due Dates. The Summary formulas read the sheet named Close Tracker, so keep the current month on that tab and archive old copies.
B14: Conventions
B15: Yellow cells are inputs; everything else computes from them. Never type over a formula cell.
B16: Statuses drive all rollups: only rows marked Done count as complete, and Blocked rows surface in the Summary blocked count so partners can unstick them fast.
... B20: The workbook ships with six sample clients and 31 tasks for a June close. Delta Property Group is fully delivered (6 of 6 done, closed in 8 days against an 8-day target), while Cedar & Vine has two blocked tasks dragging its close. Replace the sample rows with your own clients and tasks.

Sheet Clients
A1: Client | B1: Entity Count | C1: Software | D1: Close Owner | E1: Target Days to Close
A2: Acme Robotics | B2: 1 | C2: QuickBooks Online | D2: Priya S. | E2: 5
A3: Bluebird Dental | B3: 2 | C3: Xero | D3: Marcus T. | E3: 7
A4: Cedar & Vine Restaurants | B4: 3 | C4: QuickBooks Online | D4: Priya S. | E4: 10
A5: Delta Property Group | B5: 4 | C5: QuickBooks Desktop | D5: Jordan K. | E5: 8
A6: Everline SaaS | B6: 1 | C6: NetSuite | D6: Marcus T. | E6: 5
A7: Foster Community Fund | B7: 1 | C7: QuickBooks Online | D7: Jordan K. | E7: 12

Sheet Close Tracker
A1: Client | B1: Task | C1: Owner | D1: Due Date | E1: Completed Date | F1: Status | G1: Days Late
A2: Acme Robotics | B2: Bank rec | C2: Priya S. | D2: 46205 | E2: 46205 | F2: Done | G2: =IF(OR($D2="",$E2=""),"",MAX(0,$E2-$D2))
A3: Acme Robotics | B3: Credit cards | C3: Priya S. | D3: 46205 | E3: 46206 | F3: Done | G3: =IF(OR($D3="",$E3=""),"",MAX(0,$E3-$D3))
A4: Acme Robotics | B4: Accruals | C4: Priya S. | D4: 46206 | E4: 46206 | F4: Done | G4: =IF(OR($D4="",$E4=""),"",MAX(0,$E4-$D4))
A5: Acme Robotics | B5: Financials draft | C5: Priya S. | D5: 46208 | F5: In progress | G5: =IF(OR($D5="",$E5=""),"",MAX(0,$E5-$D5))
A6: Acme Robotics | B6: Partner review | C6: Dana R. | D6: 46209 | F6: Not started | G6: =IF(OR($D6="",$E6=""),"",MAX(0,$E6-$D6))
A7: Bluebird Dental | B7: Bank rec | C7: Marcus T. | D7: 46206 | E7: 46205 | F7: Done | G7: =IF(OR($D7="",$E7=""),"",MAX(0,$E7-$D7))
A8: Bluebird Dental | B8: AR review | C8: Marcus T. | D8: 46207 | E8: 46209 | F8: Done | G8: =IF(OR($D8="",$E8=""),"",MAX(0,$E8-$D8))
A9: Bluebird Dental | B9: AP cutoff | C9: Marcus T. | D9: 46207 | F9: Blocked | G9: =IF(OR($D9="",$E9=""),"",MAX(0,$E9-$D9))
A10: Bluebird Dental | B10: Payroll tie-out | C10: Sam W. | D10: 46208 | E10: 46208 | F10: Done | G10: =IF(OR($D10="",$E10=""),"",MAX(0,$E10-$D10))
A11: Bluebird Dental | B11: Financials draft | C11: Marcus T. | D11: 46211 | F11: Not started | G11: =IF(OR($D11="",$E11=""),"",MAX(0,$E11-$D11))
A12: Cedar & Vine Restaurants | B12: Bank rec | C12: Priya S. | D12: 46206 | E12: 46208 | F12: Done | G12: =IF(OR($D12="",$E12=""),"",MAX(0,$E12-$D12))
A13: Cedar & Vine Restaurants | B13: Credit cards | C13: Priya S. | D13: 46206 | E13: 46208 | F13: Done | G13: =IF(OR($D13="",$E13=""),"",MAX(0,$E13-$D13))
A14: Cedar & Vine Restaurants | B14: AP cutoff | C14: Sam W. | D14: 46208 | F14: Blocked | G14: =IF(OR($D14="",$E14=""),"",MAX(0,$E14-$D14))
A15: Cedar & Vine Restaurants | B15: Accruals | C15: Priya S. | D15: 46209 | F15: In progress | G15: =IF(OR($D15="",$E15=""),"",MAX(0,$E15-$D15))
A16: Cedar & Vine Restaurants | B16: Payroll tie-out | C16: Sam W. | D16: 46209 | F16: Blocked | G16: =IF(OR($D16="",$E16=""),"",MAX(0,$E16-$D16))
A17: Cedar & Vine Restaurants | B17: Financials draft | C17: Priya S. | D17: 46212 | F17: Not started | G17: =IF(OR($D17="",$E17=""),"",MAX(0,$E17-$D17))
A18: Delta Property Group | B18: Bank rec | C18: Jordan K. | D18: 46205 | E18: 46205 | F18: Done | G18: =IF(OR($D18="",$E18=""),"",MAX(0,$E18-$D18))
A19: Delta Property Group | B19: AR review | C19: Jordan K. | D19: 46208 | E19: 46207 | F19: Done | G19: =IF(OR($D19="",$E19=""),"",MAX(0,$E19-$D19))
A20: Delta Property Group | B20: Accruals | C20: Jordan K. | D20: 46209 | E20: 46210 | F20: Done | G20: =IF(OR($D20="",$E20=""),"",MAX(0,$E20-$D20))
A21: Delta Property Group | B21: Financials draft | C21: Jordan K. | D21: 46211 | E21: 46211 | F21: Done | G21: =IF(OR($D21="",$E21=""),"",MAX(0,$E21-$D21))
A22: Delta Property Group | B22: Partner review | C22: Dana R. | D22: 46212 | E22: 46213 | F22: Done | G22: =IF(OR($D22="",$E22=""),"",MAX(0,$E22-$D22))
A23: Delta Property Group | B23: Delivered | C23: Jordan K. | D23: 46213 | E23: 46213 | F23: Done | G23: =IF(OR($D23="",$E23=""),"",MAX(0,$E23-$D23))
A24: Everline SaaS | B24: Bank rec | C24: Marcus T. | D24: 46205 | E24: 46205 | F24: Done | G24: =IF(OR($D24="",$E24=""),"",MAX(0,$E24-$D24))
A25: Everline SaaS | B25: Credit cards | C25: Marcus T. | D25: 46205 | E25: 46205 | F25: Done | G25: =IF(OR($D25="",$E25=""),"",MAX(0,$E25-$D25))
A26: Everline SaaS | B26: Payroll tie-out | C26: Sam W. | D26: 46206 | E26: 46206 | F26: Done | G26: =IF(OR($D26="",$E26=""),"",MAX(0,$E26-$D26))
A27: Everline SaaS | B27: Accruals | C27: Marcus T. | D27: 46206 | E27: 46207 | F27: Done | G27: =IF(OR($D27="",$E27=""),"",MAX(0,$E27-$D27))
A28: Everline SaaS | B28: Financials draft | C28: Marcus T. | D28: 46208 | F28: In progress | G28: =IF(OR($D28="",$E28=""),"",MAX(0,$E28-$D28))
A29: Foster Community Fund | B29: Bank rec | C29: Jordan K. | D29: 46208 | F29: In progress | G29: =IF(OR($D29="",$E29=""),"",MAX(0,$E29-$D29))
A30: Foster Community Fund | B30: AR review | C30: Jordan K. | D30: 46209 | F30: Not started | G30: =IF(OR($D30="",$E30=""),"",MAX(0,$E30-$D30))
A31: Foster Community Fund | B31: Accruals | C31: Jordan K. | D31: 46211 | F31: Not started | G31: =IF(OR($D31="",$E31=""),"",MAX(0,$E31-$D31))
A32: Foster Community Fund | B32: Financials draft | C32: Jordan K. | D32: 46215 | F32: Not started | G32: =IF(OR($D32="",$E32=""),"",MAX(0,$E32-$D32))
G33: =IF(OR($D33="",$E33=""),"",MAX(0,$E33-$D33))
G34: =IF(OR($D34="",$E34=""),"",MAX(0,$E34-$D34))
G35: =IF(OR($D35="",$E35=""),"",MAX(0,$E35-$D35))
G36: =IF(OR($D36="",$E36=""),"",MAX(0,$E36-$D36))
G37: =IF(OR($D37="",$E37=""),"",MAX(0,$E37-$D37))
G38: =IF(OR($D38="",$E38=""),"",MAX(0,$E38-$D38))
G39: =IF(OR($D39="",$E39=""),"",MAX(0,$E39-$D39))
G40: =IF(OR($D40="",$E40=""),"",MAX(0,$E40-$D40))
...

Sheet Summary
A1: Client | B1: Target Days | C1: Tasks Total | D1: Done | E1: % Complete | F1: Blocked | G1: Days to Close So Far | H1: Vs Target (days)
A2: =Clients!A2 | B2: =VLOOKUP($A2,Clients!$A:$E,5,FALSE) | C2: =COUNTIF('Close Tracker'!$A:$A,$A2) | D2: =COUNTIFS('Close Tracker'!$A:$A,$A2,'Close Tracker'!$F:$F,"Done") | E2: =IF(C2=0,"",D2/C2) | F2: =COUNTIFS('Close Tracker'!$A:$A,$A2,'Close Tracker'!$F:$F,"Blocked") | G2: =IF(COUNTIFS('Close Tracker'!$A:$A,$A2,'Close Tracker'!$E:$E,"<>")=0,"",MAXIFS('Close Tracker'!$E:$E,'Close Tracker'!$A:$A,$A2)-MINIFS('Close Tracker'!$D:$D,'Close Tracker'!$A:$A,$A2)) | H2: =IF($G2="","",$G2-$B2)
A3: =Clients!A3 | B3: =VLOOKUP($A3,Clients!$A:$E,5,FALSE) | C3: =COUNTIF('Close Tracker'!$A:$A,$A3) | D3: =COUNTIFS('Close Tracker'!$A:$A,$A3,'Close Tracker'!$F:$F,"Done") | E3: =IF(C3=0,"",D3/C3) | F3: =COUNTIFS('Close Tracker'!$A:$A,$A3,'Close Tracker'!$F:$F,"Blocked") | G3: =IF(COUNTIFS('Close Tracker'!$A:$A,$A3,'Close Tracker'!$E:$E,"<>")=0,"",MAXIFS('Close Tracker'!$E:$E,'Close Tracker'!$A:$A,$A3)-MINIFS('Close Tracker'!$D:$D,'Close Tracker'!$A:$A,$A3)) | H3: =IF($G3="","",$G3-$B3)
A4: =Clients!A4 | B4: =VLOOKUP($A4,Clients!$A:$E,5,FALSE) | C4: =COUNTIF('Close Tracker'!$A:$A,$A4) | D4: =COUNTIFS('Close Tracker'!$A:$A,$A4,'Close Tracker'!$F:$F,"Done") | E4: =IF(C4=0,"",D4/C4) | F4: =COUNTIFS('Close Tracker'!$A:$A,$A4,'Close Tracker'!$F:$F,"Blocked") | G4: =IF(COUNTIFS('Close Tracker'!$A:$A,$A4,'Close Tracker'!$E:$E,"<>")=0,"",MAXIFS('Close Tracker'!$E:$E,'Close Tracker'!$A:$A,$A4)-MINIFS('Close Tracker'!$D:$D,'Close Tracker'!$A:$A,$A4)) | H4: =IF($G4="","",$G4-$B4)
A5: =Clients!A5 | B5: =VLOOKUP($A5,Clients!$A:$E,5,FALSE) | C5: =COUNTIF('Close Tracker'!$A:$A,$A5) | D5: =COUNTIFS('Close Tracker'!$A:$A,$A5,'Close Tracker'!$F:$F,"Done") | E5: =IF(C5=0,"",D5/C5) | F5: =COUNTIFS('Close Tracker'!$A:$A,$A5,'Close Tracker'!$F:$F,"Blocked") | G5: =IF(COUNTIFS('Close Tracker'!$A:$A,$A5,'Close Tracker'!$E:$E,"<>")=0,"",MAXIFS('Close Tracker'!$E:$E,'Close Tracker'!$A:$A,$A5)-MINIFS('Close Tracker'!$D:$D,'Close Tracker'!$A:$A,$A5)) | H5: =IF($G5="","",$G5-$B5)
A6: =Clients!A6 | B6: =VLOOKUP($A6,Clients!$A:$E,5,FALSE) | C6: =COUNTIF('Close Tracker'!$A:$A,$A6) | D6: =COUNTIFS('Close Tracker'!$A:$A,$A6,'Close Tracker'!$F:$F,"Done") | E6: =IF(C6=0,"",D6/C6) | F6: =COUNTIFS('Close Tracker'!$A:$A,$A6,'Close Tracker'!$F:$F,"Blocked") | G6: =IF(COUNTIFS('Close Tracker'!$A:$A,$A6,'Close Tracker'!$E:$E,"<>")=0,"",MAXIFS('Close Tracker'!$E:$E,'Close Tracker'!$A:$A,$A6)-MINIFS('Close Tracker'!$D:$D,'Close Tracker'!$A:$A,$A6)) | H6: =IF($G6="","",$G6-$B6)
A7: =Clients!A7 | B7: =VLOOKUP($A7,Clients!$A:$E,5,FALSE) | C7: =COUNTIF('Close Tracker'!$A:$A,$A7) | D7: =COUNTIFS('Close Tracker'!$A:$A,$A7,'Close Tracker'!$F:$F,"Done") | E7: =IF(C7=0,"",D7/C7) | F7: =COUNTIFS('Close Tracker'!$A:$A,$A7,'Close Tracker'!$F:$F,"Blocked") | G7: =IF(COUNTIFS('Close Tracker'!$A:$A,$A7,'Close Tracker'!$E:$E,"<>")=0,"",MAXIFS('Close Tracker'!$E:$E,'Close Tracker'!$A:$A,$A7)-MINIFS('Close Tracker'!$D:$D,'Close Tracker'!$A:$A,$A7)) | H7: =IF($G7="","",$G7-$B7)
A8: Firm total | C8: =SUM(C2:C7) | D8: =SUM(D2:D7) | E8: =IF(C8=0,"",D8/C8) | F8: =SUM(F2:F7) | G8: =IFERROR(AVERAGE(G2:G7),"") | H8: =IFERROR(AVERAGE(H2:H7),"")
